<?xml version="1.0" encoding="UTF-8"?>
<testng-results skipped="0" failed="4" ignored="0" total="12" passed="8">
  <reporter-output>
    <line>
      <![CDATA[test is pass in f2 of class1]]>
    </line>
    <line>
      <![CDATA[test is pass in f of class2]]>
    </line>
    <line>
      <![CDATA[test is pass in f1 of class2]]>
    </line>
    <line>
      <![CDATA[test is pass in f2 of class1]]>
    </line>
    <line>
      <![CDATA[test is pass in f2 of class1]]>
    </line>
  </reporter-output>
  <suite name="Suite" duration-ms="124" started-at="2019-06-05T02:20:35Z" finished-at="2019-06-05T02:20:36Z">
    <groups>
    </groups>
    <test name="Test" duration-ms="48" started-at="2019-06-05T02:20:35Z" finished-at="2019-06-05T02:20:35Z">
      <class name="Package1.TestClass1">
        <test-method status="PASS" signature="f()[pri:0, instance:Package1.TestClass1@3a82f6ef]" name="f" duration-ms="12" started-at="2019-06-05T02:20:35Z" finished-at="2019-06-05T02:20:35Z">
          <reporter-output>
          </reporter-output>
        </test-method> <!-- f -->
        <test-method status="FAIL" signature="f1()[pri:0, instance:Package1.TestClass1@3a82f6ef]" name="f1" duration-ms="4" started-at="2019-06-05T02:20:35Z" finished-at="2019-06-05T02:20:35Z">
          <exception class="java.lang.AssertionError">
            <message>
              <![CDATA[this is failed]]>
            </message>
            <full-stacktrace>
              <![CDATA[java.lang.AssertionError: this is failed
at org.testng.Assert.fail(Assert.java:96)
at Package1.TestClass1.f1(TestClass1.java:18)
at sun.reflect.NativeMethodAccessorImpl.invoke0(Native Method)
at sun.reflect.NativeMethodAccessorImpl.invoke(NativeMethodAccessorImpl.java:62)
at sun.reflect.DelegatingMethodAccessorImpl.invoke(DelegatingMethodAccessorImpl.java:43)
at java.lang.reflect.Method.invoke(Method.java:498)
at org.testng.internal.MethodInvocationHelper.invokeMethod(MethodInvocationHelper.java:124)
at org.testng.internal.Invoker.invokeMethod(Invoker.java:580)
at org.testng.internal.Invoker.invokeTestMethod(Invoker.java:716)
at org.testng.internal.Invoker.invokeTestMethods(Invoker.java:988)
at org.testng.internal.TestMethodWorker.invokeTestMethods(TestMethodWorker.java:125)
at org.testng.internal.TestMethodWorker.run(TestMethodWorker.java:109)
at org.testng.TestRunner.privateRun(TestRunner.java:648)
at org.testng.TestRunner.run(TestRunner.java:505)
at org.testng.SuiteRunner.runTest(SuiteRunner.java:455)
at org.testng.SuiteRunner.runSequentially(SuiteRunner.java:450)
at org.testng.SuiteRunner.privateRun(SuiteRunner.java:415)
at org.testng.SuiteRunner.run(SuiteRunner.java:364)
at org.testng.SuiteRunnerWorker.runSuite(SuiteRunnerWorker.java:52)
at org.testng.SuiteRunnerWorker.run(SuiteRunnerWorker.java:84)
at org.testng.TestNG.runSuitesSequentially(TestNG.java:1208)
at org.testng.TestNG.runSuitesLocally(TestNG.java:1137)
at org.testng.TestNG.runSuites(TestNG.java:1049)
at org.testng.TestNG.run(TestNG.java:1017)
at org.testng.remote.AbstractRemoteTestNG.run(AbstractRemoteTestNG.java:114)
at org.testng.remote.RemoteTestNG.initAndRun(RemoteTestNG.java:251)
at org.testng.remote.RemoteTestNG.main(RemoteTestNG.java:77)
]]>
            </full-stacktrace>
          </exception> <!-- java.lang.AssertionError -->
          <reporter-output>
          </reporter-output>
        </test-method> <!-- f1 -->
        <test-method status="PASS" signature="f2()[pri:0, instance:Package1.TestClass1@3a82f6ef]" name="f2" duration-ms="4" started-at="2019-06-05T02:20:35Z" finished-at="2019-06-05T02:20:35Z">
          <reporter-output>
            <line>
              <![CDATA[test is pass in f2 of class1]]>
            </line>
          </reporter-output>
        </test-method> <!-- f2 -->
      </class> <!-- Package1.TestClass1 -->
      <class name="Package1.TestClass2">
        <test-method status="PASS" signature="f()[pri:0, instance:Package1.TestClass2@2ef5e5e3]" name="f" duration-ms="0" started-at="2019-06-05T02:20:35Z" finished-at="2019-06-05T02:20:35Z">
          <reporter-output>
            <line>
              <![CDATA[test is pass in f of class2]]>
            </line>
          </reporter-output>
        </test-method> <!-- f -->
        <test-method status="FAIL" signature="f2()[pri:0, instance:Package1.TestClass2@2ef5e5e3]" name="f2" duration-ms="0" started-at="2019-06-05T02:20:35Z" finished-at="2019-06-05T02:20:35Z">
          <exception class="java.lang.AssertionError">
            <message>
              <![CDATA[this is failed in f2 of class2]]>
            </message>
            <full-stacktrace>
              <![CDATA[java.lang.AssertionError: this is failed in f2 of class2
at org.testng.Assert.fail(Assert.java:96)
at Package1.TestClass2.f2(TestClass2.java:24)
at sun.reflect.NativeMethodAccessorImpl.invoke0(Native Method)
at sun.reflect.NativeMethodAccessorImpl.invoke(NativeMethodAccessorImpl.java:62)
at sun.reflect.DelegatingMethodAccessorImpl.invoke(DelegatingMethodAccessorImpl.java:43)
at java.lang.reflect.Method.invoke(Method.java:498)
at org.testng.internal.MethodInvocationHelper.invokeMethod(MethodInvocationHelper.java:124)
at org.testng.internal.Invoker.invokeMethod(Invoker.java:580)
at org.testng.internal.Invoker.invokeTestMethod(Invoker.java:716)
at org.testng.internal.Invoker.invokeTestMethods(Invoker.java:988)
at org.testng.internal.TestMethodWorker.invokeTestMethods(TestMethodWorker.java:125)
at org.testng.internal.TestMethodWorker.run(TestMethodWorker.java:109)
at org.testng.TestRunner.privateRun(TestRunner.java:648)
at org.testng.TestRunner.run(TestRunner.java:505)
at org.testng.SuiteRunner.runTest(SuiteRunner.java:455)
at org.testng.SuiteRunner.runSequentially(SuiteRunner.java:450)
at org.testng.SuiteRunner.privateRun(SuiteRunner.java:415)
at org.testng.SuiteRunner.run(SuiteRunner.java:364)
at org.testng.SuiteRunnerWorker.runSuite(SuiteRunnerWorker.java:52)
at org.testng.SuiteRunnerWorker.run(SuiteRunnerWorker.java:84)
at org.testng.TestNG.runSuitesSequentially(TestNG.java:1208)
at org.testng.TestNG.runSuitesLocally(TestNG.java:1137)
at org.testng.TestNG.runSuites(TestNG.java:1049)
at org.testng.TestNG.run(TestNG.java:1017)
at org.testng.remote.AbstractRemoteTestNG.run(AbstractRemoteTestNG.java:114)
at org.testng.remote.RemoteTestNG.initAndRun(RemoteTestNG.java:251)
at org.testng.remote.RemoteTestNG.main(RemoteTestNG.java:77)
]]>
            </full-stacktrace>
          </exception> <!-- java.lang.AssertionError -->
          <reporter-output>
          </reporter-output>
        </test-method> <!-- f2 -->
        <test-method status="PASS" signature="f1()[pri:0, instance:Package1.TestClass2@2ef5e5e3]" name="f1" duration-ms="0" started-at="2019-06-05T02:20:35Z" finished-at="2019-06-05T02:20:35Z">
          <reporter-output>
            <line>
              <![CDATA[test is pass in f1 of class2]]>
            </line>
          </reporter-output>
        </test-method> <!-- f1 -->
      </class> <!-- Package1.TestClass2 -->
    </test> <!-- Test -->
    <test name="Test1" duration-ms="20" started-at="2019-06-05T02:20:36Z" finished-at="2019-06-05T02:20:36Z">
      <class name="Package1.Testclass3">
        <test-method status="FAIL" signature="f1()[pri:0, instance:Package1.Testclass3@4b9e13df]" name="f1" duration-ms="4" started-at="2019-06-05T02:20:36Z" finished-at="2019-06-05T02:20:36Z">
          <exception class="java.lang.AssertionError">
            <message>
              <![CDATA[this is failed]]>
            </message>
            <full-stacktrace>
              <![CDATA[java.lang.AssertionError: this is failed
at org.testng.Assert.fail(Assert.java:96)
at Package1.Testclass3.f1(Testclass3.java:15)
at sun.reflect.NativeMethodAccessorImpl.invoke0(Native Method)
at sun.reflect.NativeMethodAccessorImpl.invoke(NativeMethodAccessorImpl.java:62)
at sun.reflect.DelegatingMethodAccessorImpl.invoke(DelegatingMethodAccessorImpl.java:43)
at java.lang.reflect.Method.invoke(Method.java:498)
at org.testng.internal.MethodInvocationHelper.invokeMethod(MethodInvocationHelper.java:124)
at org.testng.internal.Invoker.invokeMethod(Invoker.java:580)
at org.testng.internal.Invoker.invokeTestMethod(Invoker.java:716)
at org.testng.internal.Invoker.invokeTestMethods(Invoker.java:988)
at org.testng.internal.TestMethodWorker.invokeTestMethods(TestMethodWorker.java:125)
at org.testng.internal.TestMethodWorker.run(TestMethodWorker.java:109)
at org.testng.TestRunner.privateRun(TestRunner.java:648)
at org.testng.TestRunner.run(TestRunner.java:505)
at org.testng.SuiteRunner.runTest(SuiteRunner.java:455)
at org.testng.SuiteRunner.runSequentially(SuiteRunner.java:450)
at org.testng.SuiteRunner.privateRun(SuiteRunner.java:415)
at org.testng.SuiteRunner.run(SuiteRunner.java:364)
at org.testng.SuiteRunnerWorker.runSuite(SuiteRunnerWorker.java:52)
at org.testng.SuiteRunnerWorker.run(SuiteRunnerWorker.java:84)
at org.testng.TestNG.runSuitesSequentially(TestNG.java:1208)
at org.testng.TestNG.runSuitesLocally(TestNG.java:1137)
at org.testng.TestNG.runSuites(TestNG.java:1049)
at org.testng.TestNG.run(TestNG.java:1017)
at org.testng.remote.AbstractRemoteTestNG.run(AbstractRemoteTestNG.java:114)
at org.testng.remote.RemoteTestNG.initAndRun(RemoteTestNG.java:251)
at org.testng.remote.RemoteTestNG.main(RemoteTestNG.java:77)
]]>
            </full-stacktrace>
          </exception> <!-- java.lang.AssertionError -->
          <reporter-output>
          </reporter-output>
        </test-method> <!-- f1 -->
        <test-method status="PASS" signature="f()[pri:0, instance:Package1.Testclass3@4b9e13df]" name="f" duration-ms="0" started-at="2019-06-05T02:20:36Z" finished-at="2019-06-05T02:20:36Z">
          <reporter-output>
          </reporter-output>
        </test-method> <!-- f -->
        <test-method status="PASS" signature="f2()[pri:0, instance:Package1.Testclass3@4b9e13df]" name="f2" duration-ms="4" started-at="2019-06-05T02:20:36Z" finished-at="2019-06-05T02:20:36Z">
          <reporter-output>
            <line>
              <![CDATA[test is pass in f2 of class1]]>
            </line>
          </reporter-output>
        </test-method> <!-- f2 -->
      </class> <!-- Package1.Testclass3 -->
      <class name="Package1.TestClass4">
        <test-method status="PASS" signature="f()[pri:0, instance:Package1.TestClass4@2b98378d]" name="f" duration-ms="0" started-at="2019-06-05T02:20:36Z" finished-at="2019-06-05T02:20:36Z">
          <reporter-output>
          </reporter-output>
        </test-method> <!-- f -->
        <test-method status="FAIL" signature="f1()[pri:0, instance:Package1.TestClass4@2b98378d]" name="f1" duration-ms="0" started-at="2019-06-05T02:20:36Z" finished-at="2019-06-05T02:20:36Z">
          <exception class="java.lang.AssertionError">
            <message>
              <![CDATA[this is failed]]>
            </message>
            <full-stacktrace>
              <![CDATA[java.lang.AssertionError: this is failed
at org.testng.Assert.fail(Assert.java:96)
at Package1.TestClass4.f1(TestClass4.java:15)
at sun.reflect.NativeMethodAccessorImpl.invoke0(Native Method)
at sun.reflect.NativeMethodAccessorImpl.invoke(NativeMethodAccessorImpl.java:62)
at sun.reflect.DelegatingMethodAccessorImpl.invoke(DelegatingMethodAccessorImpl.java:43)
at java.lang.reflect.Method.invoke(Method.java:498)
at org.testng.internal.MethodInvocationHelper.invokeMethod(MethodInvocationHelper.java:124)
at org.testng.internal.Invoker.invokeMethod(Invoker.java:580)
at org.testng.internal.Invoker.invokeTestMethod(Invoker.java:716)
at org.testng.internal.Invoker.invokeTestMethods(Invoker.java:988)
at org.testng.internal.TestMethodWorker.invokeTestMethods(TestMethodWorker.java:125)
at org.testng.internal.TestMethodWorker.run(TestMethodWorker.java:109)
at org.testng.TestRunner.privateRun(TestRunner.java:648)
at org.testng.TestRunner.run(TestRunner.java:505)
at org.testng.SuiteRunner.runTest(SuiteRunner.java:455)
at org.testng.SuiteRunner.runSequentially(SuiteRunner.java:450)
at org.testng.SuiteRunner.privateRun(SuiteRunner.java:415)
at org.testng.SuiteRunner.run(SuiteRunner.java:364)
at org.testng.SuiteRunnerWorker.runSuite(SuiteRunnerWorker.java:52)
at org.testng.SuiteRunnerWorker.run(SuiteRunnerWorker.java:84)
at org.testng.TestNG.runSuitesSequentially(TestNG.java:1208)
at org.testng.TestNG.runSuitesLocally(TestNG.java:1137)
at org.testng.TestNG.runSuites(TestNG.java:1049)
at org.testng.TestNG.run(TestNG.java:1017)
at org.testng.remote.AbstractRemoteTestNG.run(AbstractRemoteTestNG.java:114)
at org.testng.remote.RemoteTestNG.initAndRun(RemoteTestNG.java:251)
at org.testng.remote.RemoteTestNG.main(RemoteTestNG.java:77)
]]>
            </full-stacktrace>
          </exception> <!-- java.lang.AssertionError -->
          <reporter-output>
          </reporter-output>
        </test-method> <!-- f1 -->
        <test-method status="PASS" signature="f2()[pri:0, instance:Package1.TestClass4@2b98378d]" name="f2" duration-ms="4" started-at="2019-06-05T02:20:36Z" finished-at="2019-06-05T02:20:36Z">
          <reporter-output>
            <line>
              <![CDATA[test is pass in f2 of class1]]>
            </line>
          </reporter-output>
        </test-method> <!-- f2 -->
      </class> <!-- Package1.TestClass4 -->
    </test> <!-- Test1 -->
  </suite> <!-- Suite -->
</testng-results>
